Workbook

Sheet 1. Effort
I1: 2500000
B2: Effort By Module and Role
D4: Effort (MD) | J4: Cost (USD)
B5: # | C5: Module | D5: Total (MD) | E5: BE Coding (MD) | F5: FE/Mobile Coding (MD) | G5: Requirement Analysis (MD) | H5: Testing (MD) | I5: Project Management (MD) | J5: Total (USD) | K5: BE Coding (USD) | L5: FE/Mobile Coding (USD) | M5: Requirement Analysis (USD) | N5: Testing (USD) | O5: Project Management (USD)
B6: I | C6: =VLOOKUP($B6,'2. WBS'!$B$5:$L$64,2,FALSE) | D6: =SUM(E6:I6) | E6: =VLOOKUP($B6,'2. WBS'!$B$5:$L$64,6,FALSE) | F6: =VLOOKUP($B6,'2. WBS'!$B$5:$L$64,7,FALSE) | G6: =VLOOKUP($B6,'2. WBS'!$B$5:$L$64,8,FALSE) | H6: =VLOOKUP($B6,'2. WBS'!$B$5:$L$64,9,FALSE) | I6: =VLOOKUP($B6,'2. WBS'!$B$5:$L$64,10,FALSE) | J6: =SUM(K6:O6) | K6: =E6*'4. Master Data'!$C$13 | L6: =F6*'4. Master Data'!$C$13 | M6: =G6*'4. Master Data'!$C$12 | N6: =H6*'4. Master Data'!$C$14 | O6: =I6*'4. Master Data'!$C$11
B7: I.A | C7: =VLOOKUP($B7,'2. WBS'!$B$5:$L$64,2,FALSE) | D7: =SUM(E7:I7) | E7: =VLOOKUP($B7,'2. WBS'!$B$5:$L$64,6,FALSE) | F7: =VLOOKUP($B7,'2. WBS'!$B$5:$L$64,7,FALSE) | G7: =VLOOKUP($B7,'2. WBS'!$B$5:$L$64,8,FALSE) | H7: =VLOOKUP($B7,'2. WBS'!$B$5:$L$64,9,FALSE) | I7: =VLOOKUP($B7,'2. WBS'!$B$5:$L$64,10,FALSE) | J7: =SUM(K7:O7) | K7: =E7*'4. Master Data'!$C$13 | L7: =F7*'4. Master Data'!$C$13 | M7: =G7*'4. Master Data'!$C$12 | N7: =H7*'4. Master Data'!$C$14 | O7: =I7*'4. Master Data'!$C$11
B8: I.B | C8: =VLOOKUP($B8,'2. WBS'!$B$5:$L$64,2,FALSE) | D8: =SUM(E8:I8) | E8: =VLOOKUP($B8,'2. WBS'!$B$5:$L$64,6,FALSE) | F8: =VLOOKUP($B8,'2. WBS'!$B$5:$L$64,7,FALSE) | G8: =VLOOKUP($B8,'2. WBS'!$B$5:$L$64,8,FALSE) | H8: =VLOOKUP($B8,'2. WBS'!$B$5:$L$64,9,FALSE) | I8: =VLOOKUP($B8,'2. WBS'!$B$5:$L$64,10,FALSE) | J8: =SUM(K8:O8) | K8: =E8*'4. Master Data'!$C$13 | L8: =F8*'4. Master Data'!$C$13 | M8: =G8*'4. Master Data'!$C$12 | N8: =H8*'4. Master Data'!$C$14 | O8: =I8*'4. Master Data'!$C$11
B9: II | C9: =VLOOKUP($B9,'2. WBS'!$B$5:$L$64,2,FALSE) | D9: =SUM(E9:I9) | E9: =VLOOKUP($B9,'2. WBS'!$B$5:$L$64,6,FALSE) | F9: =VLOOKUP($B9,'2. WBS'!$B$5:$L$64,7,FALSE) | G9: =VLOOKUP($B9,'2. WBS'!$B$5:$L$64,8,FALSE) | H9: =VLOOKUP($B9,'2. WBS'!$B$5:$L$64,9,FALSE) | I9: =VLOOKUP($B9,'2. WBS'!$B$5:$L$64,10,FALSE) | J9: =SUM(K9:O9) | K9: =E9*'4. Master Data'!$C$13 | L9: =F9*'4. Master Data'!$C$13 | M9: =G9*'4. Master Data'!$C$12 | N9: =H9*'4. Master Data'!$C$14 | O9: =I9*'4. Master Data'!$C$11
B10: II.A | C10: =VLOOKUP($B10,'2. WBS'!$B$5:$L$64,2,FALSE) | D10: =SUM(E10:I10) | E10: =VLOOKUP($B10,'2. WBS'!$B$5:$L$64,6,FALSE) | F10: =VLOOKUP($B10,'2. WBS'!$B$5:$L$64,7,FALSE) | G10: =VLOOKUP($B10,'2. WBS'!$B$5:$L$64,8,FALSE) | H10: =VLOOKUP($B10,'2. WBS'!$B$5:$L$64,9,FALSE) | I10: =VLOOKUP($B10,'2. WBS'!$B$5:$L$64,10,FALSE) | J10: =SUM(K10:O10) | K10: =E10*'4. Master Data'!$C$13 | L10: =F10*'4. Master Data'!$C$13 | M10: =G10*'4. Master Data'!$C$12 | N10: =H10*'4. Master Data'!$C$14 | O10: =I10*'4. Master Data'!$C$11
B11: II.B | C11: =VLOOKUP($B11,'2. WBS'!$B$5:$L$64,2,FALSE) | D11: =SUM(E11:I11) | E11: =VLOOKUP($B11,'2. WBS'!$B$5:$L$64,6,FALSE) | F11: =VLOOKUP($B11,'2. WBS'!$B$5:$L$64,7,FALSE) | G11: =VLOOKUP($B11,'2. WBS'!$B$5:$L$64,8,FALSE) | H11: =VLOOKUP($B11,'2. WBS'!$B$5:$L$64,9,FALSE) | I11: =VLOOKUP($B11,'2. WBS'!$B$5:$L$64,10,FALSE) | J11: =SUM(K11:O11) | K11: =E11*'4. Master Data'!$C$13 | L11: =F11*'4. Master Data'!$C$13 | M11: =G11*'4. Master Data'!$C$12 | N11: =H11*'4. Master Data'!$C$14 | O11: =I11*'4. Master Data'!$C$11
B12: II.C | C12: =VLOOKUP($B12,'2. WBS'!$B$5:$L$64,2,FALSE) | D12: =SUM(E12:I12) | E12: =VLOOKUP($B12,'2. WBS'!$B$5:$L$64,6,FALSE) | F12: =VLOOKUP($B12,'2. WBS'!$B$5:$L$64,7,FALSE) | G12: =VLOOKUP($B12,'2. WBS'!$B$5:$L$64,8,FALSE) | H12: =VLOOKUP($B12,'2. WBS'!$B$5:$L$64,9,FALSE) | I12: =VLOOKUP($B12,'2. WBS'!$B$5:$L$64,10,FALSE) | J12: =SUM(K12:O12) | K12: =E12*'4. Master Data'!$C$13 | L12: =F12*'4. Master Data'!$C$13 | M12: =G12*'4. Master Data'!$C$12 | N12: =H12*'4. Master Data'!$C$14 | O12: =I12*'4. Master Data'!$C$11
B13: II.D | C13: =VLOOKUP($B13,'2. WBS'!$B$5:$L$64,2,FALSE) | D13: =SUM(E13:I13) | E13: =VLOOKUP($B13,'2. WBS'!$B$5:$L$64,6,FALSE) | F13: =VLOOKUP($B13,'2. WBS'!$B$5:$L$64,7,FALSE) | G13: =VLOOKUP($B13,'2. WBS'!$B$5:$L$64,8,FALSE) | H13: =VLOOKUP($B13,'2. WBS'!$B$5:$L$64,9,FALSE) | I13: =VLOOKUP($B13,'2. WBS'!$B$5:$L$64,10,FALSE) | J13: =SUM(K13:O13) | K13: =E13*'4. Master Data'!$C$13 | L13: =F13*'4. Master Data'!$C$13 | M13: =G13*'4. Master Data'!$C$12 | N13: =H13*'4. Master Data'!$C$14 | O13: =I13*'4. Master Data'!$C$11
B14: II.E | C14: =VLOOKUP($B14,'2. WBS'!$B$5:$L$64,2,FALSE) | D14: =SUM(E14:I14) | E14: =VLOOKUP($B14,'2. WBS'!$B$5:$L$64,6,FALSE) | F14: =VLOOKUP($B14,'2. WBS'!$B$5:$L$64,7,FALSE) | G14: =VLOOKUP($B14,'2. WBS'!$B$5:$L$64,8,FALSE) | H14: =VLOOKUP($B14,'2. WBS'!$B$5:$L$64,9,FALSE) | I14: =VLOOKUP($B14,'2. WBS'!$B$5:$L$64,10,FALSE) | J14: =SUM(K14:O14) | K14: =E14*'4. Master Data'!$C$13 | L14: =F14*'4. Master Data'!$C$13 | M14: =G14*'4. Master Data'!$C$12 | N14: =H14*'4. Master Data'!$C$14 | O14: =I14*'4. Master Data'!$C$11
B15: III | C15: =VLOOKUP($B15,'2. WBS'!$B$5:$L$64,2,FALSE) | D15: =SUM(E15:I15) | E15: =VLOOKUP($B15,'2. WBS'!$B$5:$L$64,6,FALSE) | F15: =VLOOKUP($B15,'2. WBS'!$B$5:$L$64,7,FALSE) | G15: =VLOOKUP($B15,'2. WBS'!$B$5:$L$64,8,FALSE) | H15: =VLOOKUP($B15,'2. WBS'!$B$5:$L$64,9,FALSE) | I15: =VLOOKUP($B15,'2. WBS'!$B$5:$L$64,10,FALSE) | J15: =SUM(K15:O15) | K15: =E15*'4. Master Data'!$C$13 | L15: =F15*'4. Master Data'!$C$13 | M15: =G15*'4. Master Data'!$C$12 | N15: =H15*'4. Master Data'!$C$14 | O15: =I15*'4. Master Data'!$C$11
B16: III.A | C16: =VLOOKUP($B16,'2. WBS'!$B$5:$L$64,2,FALSE) | D16: =SUM(E16:I16) | E16: =VLOOKUP($B16,'2. WBS'!$B$5:$L$64,6,FALSE) | F16: =VLOOKUP($B16,'2. WBS'!$B$5:$L$64,7,FALSE) | G16: =VLOOKUP($B16,'2. WBS'!$B$5:$L$64,8,FALSE) | H16: =VLOOKUP($B16,'2. WBS'!$B$5:$L$64,9,FALSE) | I16: =VLOOKUP($B16,'2. WBS'!$B$5:$L$64,10,FALSE) | J16: =SUM(K16:O16) | K16: =E16*'4. Master Data'!$C$13 | L16: =F16*'4. Master Data'!$C$13 | M16: =G16*'4. Master Data'!$C$12 | N16: =H16*'4. Master Data'!$C$14 | O16: =I16*'4. Master Data'!$C$11
B17: III.B | C17: =VLOOKUP($B17,'2. WBS'!$B$5:$L$64,2,FALSE) | D17: =SUM(E17:I17) | E17: =VLOOKUP($B17,'2. WBS'!$B$5:$L$64,6,FALSE) | F17: =VLOOKUP($B17,'2. WBS'!$B$5:$L$64,7,FALSE) | G17: =VLOOKUP($B17,'2. WBS'!$B$5:$L$64,8,FALSE) | H17: =VLOOKUP($B17,'2. WBS'!$B$5:$L$64,9,FALSE) | I17: =VLOOKUP($B17,'2. WBS'!$B$5:$L$64,10,FALSE) | J17: =SUM(K17:O17) | K17: =E17*'4. Master Data'!$C$13 | L17: =F17*'4. Master Data'!$C$13 | M17: =G17*'4. Master Data'!$C$12 | N17: =H17*'4. Master Data'!$C$14 | O17: =I17*'4. Master Data'!$C$11
C18: TOTAL | D18: =SUM(D6,D9,D15) | E18: =SUM(E6,E9,E15) | F18: =SUM(F6,F9,F15) | G18: =SUM(G6,G9,G15) | H18: =SUM(H6,H9,H15) | I18: =SUM(I6,I9,I15) | J18: =SUM(J6,J9,J15) | K18: =SUM(K6,K9,K15) | ... O18: =SUM(O6,O9,O15)

Sheet 2. WBS
C2: Project Code | D2: AIFR
B3: WBS OF AI FINANCIAL ANALYSIS, EVIDENCE & REFERENCE-CHECK PLATFORM
B5: # | C5: Ref. Code | D5: Features | E5: Description | F5: Total (MD) | G5: BE Coding (MD) | H5: FE/Mobile Coding (MD) | I5: Requirement Analysis (MD) | J5: Testing (MD) | K5: Project Management (MD) | L5: Remark | M5: Optimistic (O) | N5: Most-likely (M) | O5: Pessimistic (P) | P5: P50 (md) | Q5: P80 (md) | R5: Definition of Done
F6: =SUM(G6:K6) | G6: =SUM(G7,G20,G55) | H6: =SUM(H7,H20,H55) | I6: =SUM(I7,I20,I55) | J6: =SUM(J7,J20,J55) | K6: =SUM(K7,K20,K55)
A7: I | B7: I | C7: SET UP & INSTALLATION | F7: =SUM(G7:K7) | G7: =SUM(G8,G14) | H7: =SUM(H8,H14) | I7: =SUM(I8,I14) | J7: =SUM(J8,J14) | K7: =SUM(K8,K14)
A8: A | B8: I.A | C8: Requirement Gathering & BA | F8: =SUM(G8:K8) | G8: =SUM(G9:G12) | H8: =SUM(H9:H12) | I8: =SUM(I9:I12) | J8: =SUM(J9:J12) | K8: =SUM(K9:K12)
A9: 1 | C9: Requirements
B10: 1 | C10: =CONCATENATE($D$2&"-",B10) | D10: AIFR scope, workflow and acceptance requirements | E10: Confirm analyst workflow, input/output contract, review states, exception paths, and release acceptance criteria. | F10: =SUM(G10:K10) | I10: 6 | K10: =SUM(G10:J10)*'4. Master Data'!$C$4 | L10: BA-only requirements work | M10: 5 | N10: 6 | O10: 8 | P10: 6.1667 | Q10: 6.5877 | R10: Approved BRD/workflow map; Acceptance criteria mapped to WBS items
B11: 2 | C11: =CONCATENATE($D$2&"-",B11) | D11: Financial ratio, health rule and benchmark requirements | E11: Elicit ratio formulas, deterministic rule precedence, health bands, benchmark comparison rules, and exception handling. | F11: =SUM(G11:K11) | I11: 4 | K11: =SUM(G11:J11)*'4. Master Data'!$C$4 | L11: BA-only requirements work | M11: 3 | N11: 4 | O11: 6 | P11: 4.1667 | Q11: 4.5877 | R11: Signed-off ratio/rule catalog; Benchmark governance decisions recorded
B12: 3 | C12: =CONCATENATE($D$2&"-",B12) | D12: Evidence, audit, security and explainability requirements | E12: Define source hierarchy, citation/provenance fields, audit events, access controls, PII handling, and analyst note expectations. | F12: =SUM(G12:K12) | I12: 3 | K12: =SUM(G12:J12)*'4. Master Data'!$C$4 | L12: BA-only requirements work | M12: 2 | N12: 3 | O12: 5 | P12: 3.1667 | Q12: 3.5877 | R12: Evidence and audit schema requirements approved; Security and explanation acceptance criteria approved
A14: B | B14: I.B | C14: AI Runtime Integration & Operational Readiness | F14: =SUM(G14:K14) | G14: =SUM(G15:G18) | H14: =SUM(H15:H18) | I14: =SUM(I15:I18) | J14: =SUM(J15:J18) | K14: =SUM(K15:K18)
A15: 1 | C15: Runtime integration
B16: 4 | C16: =CONCATENATE($D$2&"-",B16) | D16: vLLM/SGLang model endpoint integration | E16: Integrate the existing vLLM/SGLang endpoint, retries/timeouts, model selection, and health checks; excludes runtime installation/base setup. | F16: =SUM(G16:K16) | G16: 6 | I16: =SUM(G16:H16)*'4. Master Data'!$C$5 | J16: =SUM(G16:H16)*'4. Master Data'!$C$7 | K16: =SUM(G16:J16)*'4. Master Data'!$C$4 | L16: Existing serving setup; endpoint integration only | M16: 4 | N16: 6 | O16: 8 | P16: 6 | Q16: 6.5613 | R16: Endpoint health check passes; Timeout/retry behavior tested; No runtime installation work included
B17: 5 | C17: =CONCATENATE($D$2&"-",B17) | D17: Tool-calling contract tests and adapter harness | E17: Implement JSON-schema tool-call contracts, mock tool adapters, invalid-call fixtures, and compatibility tests for the approved model endpoint. | F17: =SUM(G17:K17) | G17: 5 | I17: =SUM(G17:H17)*'4. Master Data'!$C$5 | J17: =SUM(G17:H17)*'4. Master Data'!$C$7 | K17: =SUM(G17:J17)*'4. Master Data'!$C$4 | L17: Contract tests only; no frontend/mobile coding | M17: 3 | N17: 5 | O17: 7 | P17: 5 | Q17: 5.5613 | R17: Valid and invalid tool-call fixtures pass; Schema-version compatibility test passes; Contract test report committed
B18: 6 | C18: =CONCATENATE($D$2&"-",B18) | D18: Model endpoint performance validation | E18: Run representative prompt/tool-call load tests, measure latency/token throughput, and document concurrency limits and fallback thresholds. | F18: =SUM(G18:K18) | G18: 4 | I18: =SUM(G18:H18)*'4. Master Data'!$C$5 | J18: =SUM(G18:H18)*'4. Master Data'!$C$7 | K18: =SUM(G18:J18)*'4. Master Data'!$C$4 | L18: Validation of existing runtime only | M18: 3 | N18: 4 | O18: 6 | P18: 4.1667 | Q18: 4.5877 | R18: Latency and throughput baseline recorded; Performance limits and fallback thresholds approved
A20: II | B20: II | C20: DEVELOPMENT | F20: =SUM(G20:K20) | G20: =SUM(G21,G32,G38,G44,G49) | H20: =SUM(H21,H32,H38,H44,H49) | I20: =SUM(I21,I32,I38,I44,I49) | J20: =SUM(J21,J32,J38,J44,J49) | K20: =SUM(K21,K32,K38,K44,K49)
A21: A | B21: II.A | C21: AI Models & Orchestration | F21: =SUM(G21:K21) | G21: =SUM(G22:G30) | H21: =SUM(H22:H30) | I21: =SUM(I22:I30) | J21: =SUM(J22:J30) | K21: =SUM(K22:K30)
A22: 1 | C22: Agent implementations
B23: 7 | C23: =CONCATENATE($D$2&"-",B23) | D23: Main Agent / LangGraph-DeepAgent orchestration | E23: Implement the typed state graph, task routing, checkpoint/resume, agent hand-offs, bounded retries, and terminal result assembly for the financial analysis workflow. | F23: =SUM(G23:K23) | G23: 6 | I23: =SUM(G23:H23)*'4. Master Data'!$C$5 | J23: =SUM(G23:H23)*'4. Master Data'!$C$7 | K23: =SUM(G23:J23)*'4. Master Data'!$C$4 | L23: Concrete orchestration implementation | M23: 4 | N23: 6 | O23: 8 | P23: 6 | Q23: 6.5613 | R23: Graph completes happy-path workflow; Checkpoint/resume preserves state; Retry limits and terminal errors are covered by tests
B24: 8 | C24: =CONCATENATE($D$2&"-",B24) | D24: Financial Ratio Agent | E24: Implement the agent adapter that requests normalized financial inputs, invokes deterministic ratio tools, and returns ratio results with source-field references. | F24: =SUM(G24:K24) | G24: 6 | I24: =SUM(G24:H24)*'4. Master Data'!$C$5 | J24: =SUM(G24:H24)*'4. Master Data'!$C$7 | K24: =SUM(G24:J24)*'4. Master Data'!$C$4 | L24: Agent-specific backend work | M24: 4 | N24: 6 | O24: 8 | P24: 6 | Q24: 6.5613 | R24: Agent invokes only registered ratio tools; Outputs include ratio IDs and source references; Missing-input path is handled deterministically
B25: 9 | C25: =CONCATENATE($D$2&"-",B25) | D25: Health Evaluation Agent | E25: Implement health-band evaluation agent that consumes computed ratios and rule outcomes, identifies drivers, and emits structured health findings. | F25: =SUM(G25:K25) | G25: 5 | I25: =SUM(G25:H25)*'4. Master Data'!$C$5 | J25: =SUM(G25:H25)*'4. Master Data'!$C$7 | K25: =SUM(G25:J25)*'4. Master Data'!$C$4 | L25: Agent-specific backend work | M25: 3 | N25: 5 | O25: 7 | P25: 5 | Q25: 5.5613 | R25: Health findings conform to schema; Each finding links to ratio/rule evidence; Threshold and exception cases are tested
B26: 10 | C26: =CONCATENATE($D$2&"-",B26) | D26: Reference-Check Agent | E26: Implement dependency/reference lookup agent using evidence search and graph queries to compare declared relationships against retrieved records. | F26: =SUM(G26:K26) | G26: 5 | I26: =SUM(G26:H26)*'4. Master Data'!$C$5 | J26: =SUM(G26:H26)*'4. Master Data'!$C$7 | K26: =SUM(G26:J26)*'4. Master Data'!$C$4 | L26: Agent-specific backend work | M26: 3 | N26: 5 | O26: 7 | P26: 5 | Q26: 5.5613 | R26: Reference queries return ranked evidence; Neo4j relationship checks are represented in output; No-evidence result is explicit and non-hallucinatory
B27: 11 | C27: =CONCATENATE($D$2&"-",B27) | D27: Industry Benchmark Agent | E27: Implement benchmark retrieval agent that selects governed peer sets, applies period/industry filters, and returns comparable metrics with coverage metadata. | F27: =SUM(G27:K27) | G27: 5 | I27: =SUM(G27:H27)*'4. Master Data'!$C$5 | J27: =SUM(G27:H27)*'4. Master Data'!$C$7 | K27: =SUM(G27:J27)*'4. Master Data'!$C$4 | L27: Agent-specific backend work | M27: 3 | N27: 5 | O27: 7 | P27: 5 | Q27: 5.5613 | R27: Peer selection uses approved governance rules; Benchmark outputs include period and coverage fields; Out-of-coverage behavior is tested
B28: 12 | C28: =CONCATENATE($D$2&"-",B28) | D28: Explanation & Note Agent | E28: Implement evidence-grounded explanation and analyst-note generation with citations, confidence/limitations, and editable note sections. | F28: =SUM(G28:K28) | G28: 5 | I28: =SUM(G28:H28)*'4. Master Data'!$C$5 | J28: =SUM(G28:H28)*'4. Master Data'!$C$7 | K28: =SUM(G28:J28)*'4. Master Data'!$C$4 | L28: Agent-specific backend work | M28: 3 | N28: 5 | O28: 7 | P28: 5 | Q28: 5.5613 | R28: Every explanation claim has evidence references or limitation text; Note schema validates; Prompt-injection and unsupported-claim fixtures are rejected
B29: 13 | C29: =CONCATENATE($D$2&"-",B29) | D29: Recommendation Support Agent | E29: Implement recommendation-support agent that turns validated findings into prioritized support points, assumptions, and analyst follow-up questions; it does not make autonomous credit decisions. | F29: =SUM(G29:K29) | G29: 4 | I29: =SUM(G29:H29)*'4. Master Data'!$C$5 | J29: =SUM(G29:H29)*'4. Master Data'!$C$7 | K29: =SUM(G29:J29)*'4. Master Data'!$C$4 | L29: Decision support only; human analyst remains accountable | M29: 3 | N29: 4 | O29: 6 | P29: 4.1667 | Q29: 4.5877 | R29: Recommendations link to validated findings; Assumptions and follow-up questions are explicit; Autonomous approval/decline output is impossible
B30: 14 | C30: =CONCATENATE($D$2&"-",B30) | D30: Tool Gateway and Output Validator | E30: Implement authenticated tool registry, request/response envelopes, schema validation, provenance propagation, allowlists, and final output validation before analyst delivery. | F30: =SUM(G30:K30) | G30: 6 | I30: =SUM(G30:H30)*'4. Master Data'!$C$5 | J30: =SUM(G30:H30)*'4. Master Data'!$C$7 | K30: =SUM(G30:J30)*'4. Master Data'!$C$4 | L30: Shared gateway and safety boundary | M30: 4 | N30: 6 | O30: 8 | P30: 6 | Q30: 6.5613 | R30: Only allowlisted tools can be called; Malformed tool/result payloads are rejected; Validated output contains provenance and audit correlation ID
A32: B | B32: II.B | C32: Deterministic Financial-Ratio & Rule Logic | F32: =SUM(G32:K32) | G32: =SUM(G33:G36) | H32: =SUM(H33:H36) | I32: =SUM(I33:I36) | J32: =SUM(J33:J36) | K32: =SUM(K33:K36)
A33: 1 | C33: Deterministic logic
B34: 15 | C34: =CONCATENATE($D$2&"-",B34) | D34: Deterministic financial ratio calculation library | E34: Implement versioned ratio formulas, input normalization, denominator/zero handling, rounding, and calculation trace records for the approved ratio catalog. | F34: =SUM(G34:K34) | G34: 6 | I34: =SUM(G34:H34)*'4. Master Data'!$C$5 | J34: =SUM(G34:H34)*'4. Master Data'!$C$7 | K34: =SUM(G34:J34)*'4. Master Data'!$C$4 | L34: No LLM arithmetic; deterministic backend logic | M34: 4 | N34: 6 | O34: 8 | P34: 6 | Q34: 6.5613 | R34: Golden test vectors pass; Formula version and inputs are recorded; Invalid/zero denominator behavior is deterministic
B35: 16 | C35: =CONCATENATE($D$2&"-",B35) | D35: Deterministic health bands and rule engine | E35: Implement configurable threshold rules, precedence, severity mapping, exception rules, and rule-evaluation evidence for health classification. | F35: =SUM(G35:K35) | G35: 5 | I35: =SUM(G35:H35)*'4. Master Data'!$C$5 | J35: =SUM(G35:H35)*'4. Master Data'!$C$7 | K35: =SUM(G35:J35)*'4. Master Data'!$C$4 | L35: Rules execute outside the model | M35: 3 | N35: 5 | O35: 7 | P35: 5 | Q35: 5.5613 | R35: Threshold boundary tests pass; Rule version and precedence are traceable; Rule outcomes expose reasons and evidence
B36: 17 | C36: =CONCATENATE($D$2&"-",B36) | D36: Financial input normalization and validation | E36: Implement typed ingestion of financial statement fields, unit/period normalization, required-field checks, and structured data-quality errors. | F36: =SUM(G36:K36) | G36: 4 | I36: =SUM(G36:H36)*'4. Master Data'!$C$5 | J36: =SUM(G36:H36)*'4. Master Data'!$C$7 | K36: =SUM(G36:J36)*'4. Master Data'!$C$4 | L36: Backend-only deterministic validation | M36: 3 | N36: 4 | O36: 6 | P36: 4.1667 | Q36: 4.5877 | R36: Units and periods normalize consistently; Required-field and quality errors are structured; Normalized fixtures feed ratio golden tests
A38: C | B38: II.C | C38: Knowledge & Evidence | F38: =SUM(G38:K38) | G38: =SUM(G39:G42) | H38: =SUM(H39:H42) | I38: =SUM(I39:I42) | J38: =SUM(J39:J42) | K38: =SUM(K39:K42)
A39: 1 | C39: Vector DB + Neo4j evidence
B40: 18 | C40: =CONCATENATE($D$2&"-",B40) | D40: Evidence document ingestion and chunk metadata | E40: Implement MinIO document retrieval, parsing/chunking metadata, source identifiers, period/company tags, and ingestion status tracking. | F40: =SUM(G40:K40) | G40: 4 | I40: =SUM(G40:H40)*'4. Master Data'!$C$5 | J40: =SUM(G40:H40)*'4. Master Data'!$C$7 | K40: =SUM(G40:J40)*'4. Master Data'!$C$4 | L40: Evidence backend only | M40: 3 | N40: 4 | O40: 6 | P40: 4.1667 | Q40: 4.5877 | R40: Documents produce stable chunk/source IDs; Ingestion failures are retryable and observable; Metadata supports company and period filtering
B41: 19 | C41: =CONCATENATE($D$2&"-",B41) | D41: Vector DB retrieval and provenance service | E41: Implement embedding-service/Qdrant indexing and similarity retrieval with filters, citation spans, source ranking, and provenance-preserving response objects. | F41: =SUM(G41:K41) | G41: 5 | I41: =SUM(G41:H41)*'4. Master Data'!$C$5 | J41: =SUM(G41:H41)*'4. Master Data'!$C$7 | K41: =SUM(G41:J41)*'4. Master Data'!$C$4 | L41: Qdrant integration; no frontend/mobile coding | M41: 3 | N41: 5 | O41: 7 | P41: 5 | Q41: 5.5613 | R41: Indexed fixtures are retrievable by semantic and metadata filters; Results include source spans and scores; Provenance survives tool gateway validation
B42: 20 | C42: =CONCATENATE($D$2&"-",B42) | D42: Neo4j evidence graph and relationship queries | E42: Implement graph entities/relationships for companies, documents, references, and dependencies plus parameterized reference-check queries and graph backup metadata. | F42: =SUM(G42:K42) | G42: 4 | I42: =SUM(G42:H42)*'4. Master Data'!$C$5 | J42: =SUM(G42:H42)*'4. Master Data'!$C$7 | K42: =SUM(G42:J42)*'4. Master Data'!$C$4 | L42: Neo4j evidence backend only | M42: 3 | N42: 4 | O42: 6 | P42: 4.1667 | Q42: 4.5877 | R42: Graph constraints and seed fixtures load; Reference queries return explainable paths; Graph evidence IDs map to source records
A44: D | B44: II.D | C44: Benchmark & Reference Check | F44: =SUM(G44:K44) | G44: =SUM(G45:G47) | H44: =SUM(H45:H47) | I44: =SUM(I45:I47) | J44: =SUM(J45:J47) | K44: =SUM(K45:K47)
A45: 1 | C45: Benchmark governance
B46: 21 | C46: =CONCATENATE($D$2&"-",B46) | D46: Benchmark dataset governance and peer-set rules | E46: Implement governed benchmark dataset versioning, peer inclusion/exclusion rules, metric definitions, period alignment, and approval metadata. | F46: =SUM(G46:K46) | G46: 4 | I46: =SUM(G46:H46)*'4. Master Data'!$C$5 | J46: =SUM(G46:H46)*'4. Master Data'!$C$7 | K46: =SUM(G46:J46)*'4. Master Data'!$C$4 | L46: Governance and backend enforcement | M46: 3 | N46: 4 | O46: 6 | P46: 4.1667 | Q46: 4.5877 | R46: Dataset versions and approvals are persisted; Peer-set rule tests pass; Metric definitions and periods are queryable
B47: 22 | C47: =CONCATENATE($D$2&"-",B47) | D47: Reference-check evidence comparison service | E47: Implement comparison of declared references to retrieved graph/vector evidence, conflict flags, confidence fields, and analyst-review queue payloads. | F47: =SUM(G47:K47) | G47: 5 | I47: =SUM(G47:H47)*'4. Master Data'!$C$5 | J47: =SUM(G47:H47)*'4. Master Data'!$C$7 | K47: =SUM(G47:J47)*'4. Master Data'!$C$4 | L47: Backend comparison service | M47: 3 | N47: 5 | O47: 7 | P47: 5 | Q47: 5.5613 | R47: Match/mismatch/unknown states are distinct; Conflicts include supporting evidence IDs; Review payload is schema-valid
...

Sheet 3. Delivery Plan
B1: Master Plan
F3: 1st Month | J3: 2nd Month | N3: 3rd Month
F4: Sprint 1 | H4: Sprint 2 | J4: Sprint 3 | L4: Sprint 4 | N4: Sprint 5 | P4: Sprint 6
B5: # | C5: Module | D5: Start | E5: End | F5: W1 | G5: W2 | H5: W3 | I5: W4 | J5: W5 | K5: W6 | L5: W7 | M5: W8 | N5: W9 | O5: W10 | P5: W11 | Q5: W12
B6: I.A | C6: =VLOOKUP($B6,'2. WBS'!$B$5:$L$64,2,FALSE) | D6: W1 | E6: W1
B7: I.B | C7: =VLOOKUP($B7,'2. WBS'!$B$5:$L$64,2,FALSE) | D7: W2 | E7: W2
B8: II.A | C8: =VLOOKUP($B8,'2. WBS'!$B$5:$L$64,2,FALSE) | D8: W3 | E8: W7
B9: II.B | C9: =VLOOKUP($B9,'2. WBS'!$B$5:$L$64,2,FALSE) | D9: W8 | E9: W8
B10: II.C | C10: =VLOOKUP($B10,'2. WBS'!$B$5:$L$64,2,FALSE) | D10: W9 | E10: W9
B11: II.D | C11: =VLOOKUP($B11,'2. WBS'!$B$5:$L$64,2,FALSE) | D11: W10 | E11: W10
B12: II.E | C12: =VLOOKUP($B12,'2. WBS'!$B$5:$L$64,2,FALSE) | D12: W11 | E12: W11
B13: III.A | C13: =VLOOKUP($B13,'2. WBS'!$B$5:$L$64,2,FALSE) | D13: W12 | E13: W12
B14: III.B | C14: =VLOOKUP($B14,'2. WBS'!$B$5:$L$64,2,FALSE) | D14: W12 | E14: W12
C16: Resource Planning
B17: 1 | C17: Project Manager | D17: TBD | E17: TBD
B18: 2 | C18: Technical Lead | D18: TBD | E18: TBD
B19: 3 | C19: Developer | D19: TBD | E19: TBD
B20: 4 | C20: Business Analyst | D20: TBD | E20: TBD
B21: 5 | C21: Quality Controller | D21: TBD | E21: TBD
B22: 6 | C22: Designer | D22: TBD | E22: TBD
B23: 7 | C23: Devops | D23: TBD | E23: TBD
B25: # | C25: Deliverables Milestone | D25: Start | E25: End | F25: Deliverables
B26: 1 | C26: Contract Signoff | D26: TBD | E26: TBD | F26: Signed contract
B27: 2 | C27: Requirement Confirmation/Signoff | D27: TBD | E27: TBD | F27: BRD
B28: 3 | C28: Development Completion and UAT Initiation | D28: TBD | E28: TBD | F28: System ready in UAT, Test Cases, Test Report
B29: 4 | C29: Completion of UAT | D29: TBD | E29: TBD | F29: Source Code, User Guide, Technical Specification
B30: 5 | C30: Completion of Post-Launch Support | D30: TBD | E30: TBD | F30: Maintenance log

Sheet 4. Master Data
B2: BU
B3: Role | C3: Percent on Dev | D3: Remark
B4: PM | C4: 0.1 | D4: in total (dev + ba + qc)
B5: BA | C5: 0.1
B6: Developer
B7: QC | C7: 0.3
B9: OB
B10: Role | C10: Rate
B11: PM | C11: 200
B12: BA | C12: 130
B13: Developer | C13: 150
B14: QC | C14: 110
